<?xml version="1.0"?>

<robot name="amr_robot" xmlns:xacro="http://www.ros.org/wiki/xacro">

  <!-- ========================================================= -->
  <!-- Robot Parameters                                           -->
  <!-- ========================================================= -->

  <xacro:property name="base_length" value="0.40"/>
  <xacro:property name="base_width" value="0.30"/>
  <xacro:property name="base_height" value="0.15"/>

  <xacro:property name="wheel_radius" value="0.05"/>
  <xacro:property name="wheel_width" value="0.03"/>

  <xacro:property name="wheel_offset_x" value="0.0"/>
  <xacro:property name="wheel_offset_y" value="0.16"/>
  <xacro:property name="wheel_offset_z" value="-0.05"/>

  <!-- ========================================================= -->
  <!-- Materials                                                  -->
  <!-- ========================================================= -->

  <material name="blue">
    <color rgba="0.05 0.25 0.80 1.0"/>
  </material>

  <material name="black">
    <color rgba="0.10 0.10 0.10 1.0"/>
  </material>

  <material name="red">
    <color rgba="0.85 0.05 0.05 1.0"/>
  </material>

  <!-- ========================================================= -->
  <!-- Base Footprint                                             -->
  <!-- ========================================================= -->

  <link name="base_footprint"/>

  <!-- ========================================================= -->
  <!-- Base Link                                                  -->
  <!-- ========================================================= -->

  <joint name="base_joint" type="fixed">

    <parent link="base_footprint"/>

    <child link="base_link"/>

    <origin xyz="0 0 ${base_height/2}" rpy="0 0 0"/>

  </joint>

  <link name="base_link">

    <visual>

      <geometry>

        <box size="${base_length}
                   ${base_width}
                   ${base_height}"/>

      </geometry>

      <material name="blue"/>

    </visual>

    <collision>

      <geometry>

        <box size="${base_length}
                   ${base_width}
                   ${base_height}"/>

      </geometry>

    </collision>

    <inertial>

      <mass value="5.0"/>

      <origin xyz="0 0 0"/>

      <inertia
          ixx="0.10"
          iyy="0.10"
          izz="0.10"
          ixy="0"
          ixz="0"
          iyz="0"/>

    </inertial>

  </link>

  <!-- ========================================================= -->
  <!-- Left Wheel                                                 -->
  <!-- ========================================================= -->

  <joint name="left_wheel_joint"
         type="continuous">

    <parent link="base_link"/>

    <child link="left_wheel"/>

    <origin
        xyz="${wheel_offset_x}
             ${wheel_offset_y}
             ${wheel_offset_z}"

        rpy="1.5708 0 0"/>

    <axis xyz="0 1 0"/>

  </joint>

  <link name="left_wheel">

    <visual>

      <geometry>

        <cylinder
            radius="${wheel_radius}"
            length="${wheel_width}"/>

      </geometry>

      <material name="black"/>

    </visual>

  </link>

  <!-- ========================================================= -->
  <!-- Right Wheel                                                -->
  <!-- ========================================================= -->

  <joint name="right_wheel_joint"
         type="continuous">

    <parent link="base_link"/>

    <child link="right_wheel"/>

    <origin
        xyz="${wheel_offset_x}
             -${wheel_offset_y}
             ${wheel_offset_z}"

        rpy="1.5708 0 0"/>

    <axis xyz="0 1 0"/>

  </joint>

  <link name="right_wheel">

    <visual>

      <geometry>

        <cylinder
            radius="${wheel_radius}"
            length="${wheel_width}"/>

      </geometry>

      <material name="black"/>

    </visual>

  </link>

  <!-- ========================================================= -->
  <!-- LiDAR                                                      -->
  <!-- ========================================================= -->

  <joint name="lidar_joint"
         type="fixed">

    <parent link="base_link"/>

    <child link="lidar_link"/>

    <origin xyz="0 0 0.12"/>

  </joint>

  <link name="lidar_link">

    <visual>

      <geometry>

        <cylinder
            radius="0.03"
            length="0.05"/>

      </geometry>

      <material name="red"/>

    </visual>

  </link>

</robot>
